{
    "dataType": "CVE_RECORD",
    "dataVersion": "5.1",
    "cveMetadata": {
        "cveId": "CVE-2025-4516",
        "assignerOrgId": "28c92f92-d60d-412d-b760-e73465c3df22",
        "state": "PUBLISHED",
        "assignerShortName": "PSF",
        "dateReserved": "2025-05-09T14:59:53.878Z",
        "datePublished": "2025-05-15T13:29:20.126Z",
        "dateUpdated": "2025-05-15T13:34:16.043Z"
    },
    "containers": {
        "cna": {
            "affected": [
                {
                    "defaultStatus": "unaffected",
                    "product": "CPython",
                    "repo": "https://github.com/python/cpython",
                    "vendor": "Python Software Foundation",
                    "versions": [
                        {
                            "lessThan": "3.14.0b1",
                            "status": "affected",
                            "version": "0",
                            "versionType": "python"
                        }
                    ]
                }
            ],
            "descriptions": [
                {
                    "lang": "en",
                    "supportingMedia": [
                        {
                            "base64": false,
                            "type": "text/html",
                            "value": "There is an issue in CPython when using `bytes.decode(\"unicode_escape\", error=\"ignore|replace\")`. If you are not using the \"unicode_escape\" encoding or an error handler your usage is not affected. To work-around this issue you may stop using the error= handler and instead wrap the bytes.decode() call in a try-except catching the DecodeError."
                        }
                    ],
                    "value": "There is an issue in CPython when using `bytes.decode(\"unicode_escape\", error=\"ignore|replace\")`. If you are not using the \"unicode_escape\" encoding or an error handler your usage is not affected. To work-around this issue you may stop using the error= handler and instead wrap the bytes.decode() call in a try-except catching the DecodeError."
                }
            ],
            "metrics": [
                {
                    "cvssV4_0": {
                        "Automatable": "NOT_DEFINED",
                        "Recovery": "NOT_DEFINED",
                        "Safety": "NOT_DEFINED",
                        "attackComplexity": "HIGH",
                        "attackRequirements": "PRESENT",
                        "attackVector": "LOCAL",
                        "baseScore": 5.9,
                        "baseSeverity": "MEDIUM",
                        "privilegesRequired": "NONE",
                        "providerUrgency": "NOT_DEFINED",
                        "subAvailabilityImpact": "NONE",
                        "subConfidentialityImpact": "NONE",
                        "subIntegrityImpact": "NONE",
                        "userInteraction": "NONE",
                        "valueDensity": "NOT_DEFINED",
                        "vectorString": "CVSS:4.0/AV:L/AC:H/AT:P/PR:N/UI:N/VC:N/VI:N/VA:H/SC:N/SI:N/SA:N",
                        "version": "4.0",
                        "vulnAvailabilityImpact": "HIGH",
                        "vulnConfidentialityImpact": "NONE",
                        "vulnIntegrityImpact": "NONE",
                        "vulnerabilityResponseEffort": "NOT_DEFINED"
                    },
                    "format": "CVSS",
                    "scenarios": [
                        {
                            "lang": "en",
                            "value": "GENERAL"
                        }
                    ]
                }
            ],
            "problemTypes": [
                {
                    "descriptions": [
                        {
                            "cweId": "CWE-416",
                            "description": "CWE-416 Use After Free",
                            "lang": "en",
                            "type": "CWE"
                        }
                    ]
                }
            ],
            "providerMetadata": {
                "orgId": "28c92f92-d60d-412d-b760-e73465c3df22",
                "shortName": "PSF",
                "dateUpdated": "2025-05-15T13:34:16.043Z"
            },
            "references": [
                {
                    "tags": [
                        "issue-tracking"
                    ],
                    "url": "https://github.com/python/cpython/issues/133767"
                },
                {
                    "tags": [
                        "patch"
                    ],
                    "url": "https://github.com/python/cpython/pull/129648"
                },
                {
                    "tags": [
                        "vendor-advisory"
                    ],
                    "url": "https://mail.python.org/archives/list/security-announce@python.org/thread/L75IPBBTSCYEF56I2M4KIW353BB3AY74/"
                }
            ],
            "source": {
                "discovery": "UNKNOWN"
            },
            "title": "Use-after-free in \"unicode_escape\" decoder with error handler",
            "x_generator": {
                "engine": "Vulnogram 0.2.0"
            }
        }
    }
}