{
    "dataType": "CVE_RECORD",
    "dataVersion": "5.1",
    "cveMetadata": {
        "cveId": "CVE-2025-53366",
        "assignerOrgId": "a0819718-46f1-4df5-94e2-005712e83aaa",
        "state": "PUBLISHED",
        "assignerShortName": "GitHub_M",
        "dateReserved": "2025-06-27T12:57:16.121Z",
        "datePublished": "2025-07-04T22:05:02.975Z",
        "dateUpdated": "2025-07-04T22:05:02.975Z"
    },
    "containers": {
        "cna": {
            "title": "MCP SDK Vulnerable to FastMCP Server Validation Error, Leading to Denial of Service",
            "problemTypes": [
                {
                    "descriptions": [
                        {
                            "cweId": "CWE-248",
                            "lang": "en",
                            "description": "CWE-248: Uncaught Exception",
                            "type": "CWE"
                        }
                    ]
                }
            ],
            "metrics": [
                {
                    "cvssV4_0": {
                        "attackVector": "NETWORK",
                        "attackComplexity": "LOW",
                        "attackRequirements": "NONE",
                        "privilegesRequired": "NONE",
                        "userInteraction": "NONE",
                        "vulnConfidentialityImpact": "NONE",
                        "vulnIntegrityImpact": "NONE",
                        "vulnAvailabilityImpact": "HIGH",
                        "subConfidentialityImpact": "NONE",
                        "subIntegrityImpact": "NONE",
                        "subAvailabilityImpact": "NONE",
                        "baseScore": 8.7,
                        "baseSeverity": "HIGH",
                        "vectorString": "CVSS:4.0/AV:N/AC:L/AT:N/PR:N/UI:N/VC:N/VI:N/VA:H/SC:N/SI:N/SA:N",
                        "version": "4.0"
                    }
                }
            ],
            "references": [
                {
                    "name": "https://github.com/modelcontextprotocol/python-sdk/security/advisories/GHSA-3qhf-m339-9g5v",
                    "tags": [
                        "x_refsource_CONFIRM"
                    ],
                    "url": "https://github.com/modelcontextprotocol/python-sdk/security/advisories/GHSA-3qhf-m339-9g5v"
                },
                {
                    "name": "https://github.com/modelcontextprotocol/python-sdk/pull/822",
                    "tags": [
                        "x_refsource_MISC"
                    ],
                    "url": "https://github.com/modelcontextprotocol/python-sdk/pull/822"
                },
                {
                    "name": "https://github.com/modelcontextprotocol/python-sdk/commit/29c69e6a47d0104d0afcea6ac35e7ab02fde809a",
                    "tags": [
                        "x_refsource_MISC"
                    ],
                    "url": "https://github.com/modelcontextprotocol/python-sdk/commit/29c69e6a47d0104d0afcea6ac35e7ab02fde809a"
                }
            ],
            "affected": [
                {
                    "vendor": "modelcontextprotocol",
                    "product": "python-sdk",
                    "versions": [
                        {
                            "version": "< 1.9.4",
                            "status": "affected"
                        }
                    ]
                }
            ],
            "providerMetadata": {
                "orgId": "a0819718-46f1-4df5-94e2-005712e83aaa",
                "shortName": "GitHub_M",
                "dateUpdated": "2025-07-04T22:05:02.975Z"
            },
            "descriptions": [
                {
                    "lang": "en",
                    "value": "The MCP Python SDK, called `mcp` on PyPI, is a Python implementation of the Model Context Protocol (MCP). Prior to version 1.9.4, a validation error in the MCP SDK can cause an unhandled exception when processing malformed requests, resulting in service unavailability (500 errors) until manually restarted. Impact may vary depending on the deployment conditions, and presence of infrastructure-level resilience measures. Version 1.9.4 contains a patch for the issue."
                }
            ],
            "source": {
                "advisory": "GHSA-3qhf-m339-9g5v",
                "discovery": "UNKNOWN"
            }
        }
    }
}